2021-10-07 21:55:09,019886 - sanic.error - ERROR - <Questions: 27> is not JSON serializable
Traceback (most recent call last):
  File "/Users/vivek/Desktop/sanic_3/env/lib/python3.8/site-packages/sanic/app.py", line 770, in handle_request
    response = await response
  File "/Users/vivek/Desktop/sanic_3/app/routes/question_details.py", line 18, in show_question
    return send_response(json.dumps(
  File "/Users/vivek/Desktop/sanic_3/env/lib/python3.8/site-packages/torpedo/handlers.py", line 30, in send_response
    return json(body=data, status=status_code)
  File "/Users/vivek/Desktop/sanic_3/env/lib/python3.8/site-packages/sanic/response.py", line 286, in json
    dumps(body, **kwargs),
TypeError: <Questions: 27> is not JSON serializable
2021-10-07 21:55:36,025681 - sanic.error - ERROR - <Questions: 27> is not JSON serializable
Traceback (most recent call last):
  File "/Users/vivek/Desktop/sanic_3/env/lib/python3.8/site-packages/sanic/app.py", line 770, in handle_request
    response = await response
  File "/Users/vivek/Desktop/sanic_3/app/routes/question_details.py", line 18, in show_question
    return send_response(json.dumps(_response))
  File "/Users/vivek/Desktop/sanic_3/env/lib/python3.8/site-packages/torpedo/handlers.py", line 30, in send_response
    return json(body=data, status=status_code)
  File "/Users/vivek/Desktop/sanic_3/env/lib/python3.8/site-packages/sanic/response.py", line 286, in json
    dumps(body, **kwargs),
TypeError: <Questions: 27> is not JSON serializable
2021-10-07 21:57:08,243621 - sanic.error - ERROR - <Questions: 27> is not JSON serializable
Traceback (most recent call last):
  File "/Users/vivek/Desktop/sanic_3/env/lib/python3.8/site-packages/sanic/app.py", line 770, in handle_request
    response = await response
  File "/Users/vivek/Desktop/sanic_3/app/routes/question_details.py", line 25, in show_question_by_id
    return send_response({'message': json.dumps(
  File "/Users/vivek/Desktop/sanic_3/env/lib/python3.8/site-packages/torpedo/handlers.py", line 30, in send_response
    return json(body=data, status=status_code)
  File "/Users/vivek/Desktop/sanic_3/env/lib/python3.8/site-packages/sanic/response.py", line 286, in json
    dumps(body, **kwargs),
TypeError: <Questions: 27> is not JSON serializable
2021-10-07 21:57:44,775936 - sanic.error - ERROR - protocol.connection_task uncaught
Traceback (most recent call last):
  File "/Users/vivek/Desktop/sanic_3/env/lib/python3.8/site-packages/sanic/http.py", line 130, in http1
    await self.http1_request_header()
  File "/Users/vivek/Desktop/sanic_3/env/lib/python3.8/site-packages/sanic/http.py", line 203, in http1_request_header
    await self._receive_more()
  File "/Users/vivek/Desktop/sanic_3/env/lib/python3.8/site-packages/sanic/server.py", line 222, in receive_more
    await self._data_received.wait()
  File "/Library/Frameworks/Python.framework/Versions/3.8/lib/python3.8/asyncio/locks.py", line 309, in wait
    await fut
asyncio.exceptions.CancelledError

During handling of the above exception, another exception occurred:

Traceback (most recent call last):
  File "/Users/vivek/Desktop/sanic_3/env/lib/python3.8/site-packages/sanic/server.py", line 197, in connection_task
    await self._http.http1()
  File "/Users/vivek/Desktop/sanic_3/env/lib/python3.8/site-packages/sanic/http.py", line 146, in http1
    await self.error_response(e)
  File "/Users/vivek/Desktop/sanic_3/env/lib/python3.8/site-packages/sanic/http.py", line 420, in error_response
    await app.handle_exception(self.request, exception)
  File "/Users/vivek/Desktop/sanic_3/env/lib/python3.8/site-packages/sanic/app.py", line 704, in handle_exception
    await response.send(end_stream=True)
  File "/Users/vivek/Desktop/sanic_3/env/lib/python3.8/site-packages/sanic/response.py", line 122, in send
    await self.stream.send(data, end_stream=end_stream)
  File "/Users/vivek/Desktop/sanic_3/env/lib/python3.8/site-packages/sanic/http.py", line 348, in http1_response_header
    self.log_response()
  File "/Users/vivek/Desktop/sanic_3/env/lib/python3.8/site-packages/sanic/http.py", line 457, in log_response
    extra["request"] = f"{req.method} {req.url}"
  File "/Users/vivek/Desktop/sanic_3/env/lib/python3.8/site-packages/sanic/request.py", line 669, in url
    (self.scheme, self.host, self.path, None, self.query_string, None)
  File "/Users/vivek/Desktop/sanic_3/env/lib/python3.8/site-packages/sanic/request.py", line 596, in scheme
    if self.transport.get_extra_info("sslcontext"):
AttributeError: 'NoneType' object has no attribute 'get_extra_info'
2021-10-07 22:25:53,030479 - sanic.error - ERROR - Object does not exist
Traceback (most recent call last):
  File "/Users/vivek/Desktop/sanic_3/env/lib/python3.8/site-packages/sanic/app.py", line 770, in handle_request
    response = await response
  File "/Users/vivek/Desktop/sanic_3/app/routes/answer_details.py", line 17, in show_answer_by_id
    async def show_answer_by_id(request, id):
  File "/Users/vivek/Desktop/sanic_3/app/managers/answer_manager.py", line 19, in get_answer_by_id
    answers = await Answers.get(id=answer_id)
  File "/Users/vivek/Desktop/sanic_3/env/lib/python3.8/site-packages/tortoise/queryset.py", line 920, in _execute
    raise DoesNotExist("Object does not exist")
tortoise.exceptions.DoesNotExist: Object does not exist
2021-10-07 22:26:17,133372 - sanic.error - ERROR - protocol.connection_task uncaught
Traceback (most recent call last):
  File "/Users/vivek/Desktop/sanic_3/env/lib/python3.8/site-packages/sanic/http.py", line 130, in http1
    await self.http1_request_header()
  File "/Users/vivek/Desktop/sanic_3/env/lib/python3.8/site-packages/sanic/http.py", line 203, in http1_request_header
    await self._receive_more()
  File "/Users/vivek/Desktop/sanic_3/env/lib/python3.8/site-packages/sanic/server.py", line 222, in receive_more
    await self._data_received.wait()
  File "/Library/Frameworks/Python.framework/Versions/3.8/lib/python3.8/asyncio/locks.py", line 309, in wait
    await fut
asyncio.exceptions.CancelledError

During handling of the above exception, another exception occurred:

Traceback (most recent call last):
  File "/Users/vivek/Desktop/sanic_3/env/lib/python3.8/site-packages/sanic/server.py", line 197, in connection_task
    await self._http.http1()
  File "/Users/vivek/Desktop/sanic_3/env/lib/python3.8/site-packages/sanic/http.py", line 146, in http1
    await self.error_response(e)
  File "/Users/vivek/Desktop/sanic_3/env/lib/python3.8/site-packages/sanic/http.py", line 420, in error_response
    await app.handle_exception(self.request, exception)
  File "/Users/vivek/Desktop/sanic_3/env/lib/python3.8/site-packages/sanic/app.py", line 704, in handle_exception
    await response.send(end_stream=True)
  File "/Users/vivek/Desktop/sanic_3/env/lib/python3.8/site-packages/sanic/response.py", line 122, in send
    await self.stream.send(data, end_stream=end_stream)
  File "/Users/vivek/Desktop/sanic_3/env/lib/python3.8/site-packages/sanic/http.py", line 348, in http1_response_header
    self.log_response()
  File "/Users/vivek/Desktop/sanic_3/env/lib/python3.8/site-packages/sanic/http.py", line 457, in log_response
    extra["request"] = f"{req.method} {req.url}"
  File "/Users/vivek/Desktop/sanic_3/env/lib/python3.8/site-packages/sanic/request.py", line 669, in url
    (self.scheme, self.host, self.path, None, self.query_string, None)
  File "/Users/vivek/Desktop/sanic_3/env/lib/python3.8/site-packages/sanic/request.py", line 596, in scheme
    if self.transport.get_extra_info("sslcontext"):
AttributeError: 'NoneType' object has no attribute 'get_extra_info'
2021-10-07 22:26:27,873053 - sanic.error - ERROR - 'function' object has no attribute 'dumps'
Traceback (most recent call last):
  File "/Users/vivek/Desktop/sanic_3/env/lib/python3.8/site-packages/sanic/app.py", line 770, in handle_request
    response = await response
  File "/Users/vivek/Desktop/sanic_3/app/routes/answer_details.py", line 12, in show_answer
    return send_response({'message': json.dumps(
AttributeError: 'function' object has no attribute 'dumps'
2021-10-07 22:26:36,289687 - sanic.error - ERROR - Object does not exist
Traceback (most recent call last):
  File "/Users/vivek/Desktop/sanic_3/env/lib/python3.8/site-packages/sanic/app.py", line 770, in handle_request
    response = await response
  File "/Users/vivek/Desktop/sanic_3/app/routes/answer_details.py", line 18, in show_answer_by_id
    _response = await AnswerManager.get_answer_by_id(request, id)
  File "/Users/vivek/Desktop/sanic_3/app/managers/answer_manager.py", line 19, in get_answer_by_id
    answers = await Answers.get(id=answer_id)
  File "/Users/vivek/Desktop/sanic_3/env/lib/python3.8/site-packages/tortoise/queryset.py", line 920, in _execute
    raise DoesNotExist("Object does not exist")
tortoise.exceptions.DoesNotExist: Object does not exist
2021-10-07 22:39:23,661542 - sanic.error - ERROR - Object does not exist
Traceback (most recent call last):
  File "/Users/vivek/Desktop/sanic_3/env/lib/python3.8/site-packages/sanic/app.py", line 770, in handle_request
    response = await response
  File "/Users/vivek/Desktop/sanic_3/app/routes/answer_details.py", line 19, in show_answer_by_id
    _response = await AnswerManager.get_answer_by_id(request, id)
  File "/Users/vivek/Desktop/sanic_3/app/managers/answer_manager.py", line 20, in get_answer_by_id
    answers = await Answers.get(id=answer_id)
  File "/Users/vivek/Desktop/sanic_3/env/lib/python3.8/site-packages/tortoise/queryset.py", line 920, in _execute
    raise DoesNotExist("Object does not exist")
tortoise.exceptions.DoesNotExist: Object does not exist
2021-10-07 22:48:46,100139 - sanic.error - ERROR - 'function' object has no attribute 'dumps'
Traceback (most recent call last):
  File "/Users/vivek/Desktop/sanic_3/env/lib/python3.8/site-packages/sanic/app.py", line 770, in handle_request
    response = await response
  File "/Users/vivek/Desktop/sanic_3/app/routes/answer_details.py", line 13, in show_answer
    return send_response({'message': json.dumps(
AttributeError: 'function' object has no attribute 'dumps'
2021-10-07 22:48:59,497345 - sanic.error - ERROR - get_question_by_id() missing 1 required positional argument: 'question_id'
Traceback (most recent call last):
  File "/Users/vivek/Desktop/sanic_3/env/lib/python3.8/site-packages/sanic/app.py", line 770, in handle_request
    response = await response
  File "/Users/vivek/Desktop/sanic_3/app/routes/answer_details.py", line 26, in create_answer
    _response = await AnswerManager.create_answer(request)
  File "/Users/vivek/Desktop/sanic_3/app/managers/answer_manager.py", line 26, in create_answer
    question_id = await QuestionManager.get_question_by_id({'question_text': 'what is python??'})
TypeError: get_question_by_id() missing 1 required positional argument: 'question_id'
2021-10-07 22:49:19,584573 - sanic.error - ERROR - get_question_by_id() missing 1 required positional argument: 'question_id'
Traceback (most recent call last):
  File "/Users/vivek/Desktop/sanic_3/env/lib/python3.8/site-packages/sanic/app.py", line 770, in handle_request
    response = await response
  File "/Users/vivek/Desktop/sanic_3/app/routes/answer_details.py", line 26, in create_answer
    _response = await AnswerManager.create_answer(request)
  File "/Users/vivek/Desktop/sanic_3/app/managers/answer_manager.py", line 26, in create_answer
    question_id = await QuestionManager.get_question_by_id({'question_text': 'what is python??'})
TypeError: get_question_by_id() missing 1 required positional argument: 'question_id'
2021-10-07 22:50:54,442083 - sanic.error - ERROR - get_question_by_id() missing 1 required positional argument: 'question_id'
Traceback (most recent call last):
  File "/Users/vivek/Desktop/sanic_3/env/lib/python3.8/site-packages/sanic/app.py", line 770, in handle_request
    response = await response
  File "/Users/vivek/Desktop/sanic_3/app/routes/answer_details.py", line 26, in create_answer
    _response = await AnswerManager.create_answer(request)
  File "/Users/vivek/Desktop/sanic_3/app/managers/answer_manager.py", line 26, in create_answer
    question_id = await QuestionManager.get_question_by_id({'question_text': 'what is python??'})
TypeError: get_question_by_id() missing 1 required positional argument: 'question_id'
2021-10-07 22:51:17,851806 - sanic.error - ERROR - get_question_by_id() missing 1 required positional argument: 'question_id'
Traceback (most recent call last):
  File "/Users/vivek/Desktop/sanic_3/env/lib/python3.8/site-packages/sanic/app.py", line 770, in handle_request
    response = await response
  File "/Users/vivek/Desktop/sanic_3/app/routes/answer_details.py", line 26, in create_answer
    _response = await AnswerManager.create_answer(request)
  File "/Users/vivek/Desktop/sanic_3/app/managers/answer_manager.py", line 26, in create_answer
    question_id = await QuestionManager.get_question_by_id({'question_text': 'what is python??'})
TypeError: get_question_by_id() missing 1 required positional argument: 'question_id'
2021-10-07 23:07:03,731666 - sanic.error - ERROR - 'function' object has no attribute 'dumps'
Traceback (most recent call last):
  File "/Users/vivek/Desktop/sanic_3/env/lib/python3.8/site-packages/sanic/app.py", line 770, in handle_request
    response = await response
  File "/Users/vivek/Desktop/sanic_3/app/routes/answer_details.py", line 13, in show_answer
    return send_response({'message': json.dumps(
AttributeError: 'function' object has no attribute 'dumps'
2021-10-07 23:09:27,070287 - sanic.error - ERROR - Object does not exist
Traceback (most recent call last):
  File "/Users/vivek/Desktop/sanic_3/env/lib/python3.8/site-packages/sanic/app.py", line 770, in handle_request
    response = await response
  File "/Users/vivek/Desktop/sanic_3/app/routes/answer_details.py", line 18, in show_answer_by_id
    _response = await AnswerManager.get_answer_by_id(request, id)
  File "/Users/vivek/Desktop/sanic_3/app/managers/answer_manager.py", line 20, in get_answer_by_id
    answers = await Answers.get(id=answer_id)
  File "/Users/vivek/Desktop/sanic_3/env/lib/python3.8/site-packages/tortoise/queryset.py", line 920, in _execute
    raise DoesNotExist("Object does not exist")
tortoise.exceptions.DoesNotExist: Object does not exist
2021-10-07 23:10:15,116078 - sanic.error - ERROR - protocol.connection_task uncaught
Traceback (most recent call last):
  File "/Users/vivek/Desktop/sanic_3/env/lib/python3.8/site-packages/sanic/http.py", line 130, in http1
    await self.http1_request_header()
  File "/Users/vivek/Desktop/sanic_3/env/lib/python3.8/site-packages/sanic/http.py", line 203, in http1_request_header
    await self._receive_more()
  File "/Users/vivek/Desktop/sanic_3/env/lib/python3.8/site-packages/sanic/server.py", line 222, in receive_more
    await self._data_received.wait()
  File "/Library/Frameworks/Python.framework/Versions/3.8/lib/python3.8/asyncio/locks.py", line 309, in wait
    await fut
asyncio.exceptions.CancelledError

During handling of the above exception, another exception occurred:

Traceback (most recent call last):
  File "/Users/vivek/Desktop/sanic_3/env/lib/python3.8/site-packages/sanic/server.py", line 197, in connection_task
    await self._http.http1()
  File "/Users/vivek/Desktop/sanic_3/env/lib/python3.8/site-packages/sanic/http.py", line 146, in http1
    await self.error_response(e)
  File "/Users/vivek/Desktop/sanic_3/env/lib/python3.8/site-packages/sanic/http.py", line 420, in error_response
    await app.handle_exception(self.request, exception)
  File "/Users/vivek/Desktop/sanic_3/env/lib/python3.8/site-packages/sanic/app.py", line 704, in handle_exception
    await response.send(end_stream=True)
  File "/Users/vivek/Desktop/sanic_3/env/lib/python3.8/site-packages/sanic/response.py", line 122, in send
    await self.stream.send(data, end_stream=end_stream)
  File "/Users/vivek/Desktop/sanic_3/env/lib/python3.8/site-packages/sanic/http.py", line 348, in http1_response_header
    self.log_response()
  File "/Users/vivek/Desktop/sanic_3/env/lib/python3.8/site-packages/sanic/http.py", line 457, in log_response
    extra["request"] = f"{req.method} {req.url}"
  File "/Users/vivek/Desktop/sanic_3/env/lib/python3.8/site-packages/sanic/request.py", line 669, in url
    (self.scheme, self.host, self.path, None, self.query_string, None)
  File "/Users/vivek/Desktop/sanic_3/env/lib/python3.8/site-packages/sanic/request.py", line 596, in scheme
    if self.transport.get_extra_info("sslcontext"):
AttributeError: 'NoneType' object has no attribute 'get_extra_info'
2021-10-07 23:10:40,592183 - sanic.error - ERROR - Object does not exist
Traceback (most recent call last):
  File "/Users/vivek/Desktop/sanic_3/env/lib/python3.8/site-packages/sanic/app.py", line 770, in handle_request
    response = await response
  File "/Users/vivek/Desktop/sanic_3/app/routes/answer_details.py", line 18, in show_answer_by_id
    _response = await AnswerManager.get_answer_by_id(request, id)
  File "/Users/vivek/Desktop/sanic_3/app/managers/answer_manager.py", line 20, in get_answer_by_id
    answers = await Answers.get(id=answer_id)
  File "/Users/vivek/Desktop/sanic_3/env/lib/python3.8/site-packages/tortoise/queryset.py", line 920, in _execute
    raise DoesNotExist("Object does not exist")
tortoise.exceptions.DoesNotExist: Object does not exist
2021-10-07 23:29:44,038625 - sanic.error - ERROR - get_question_by_id() missing 1 required positional argument: 'question_id'
Traceback (most recent call last):
  File "/Users/vivek/Desktop/sanic_3/env/lib/python3.8/site-packages/sanic/app.py", line 770, in handle_request
    response = await response
  File "/Users/vivek/Desktop/sanic_3/app/routes/answer_details.py", line 25, in create_answer
    _response = await AnswerManager.create_answer(request)
  File "/Users/vivek/Desktop/sanic_3/app/managers/answer_manager.py", line 26, in create_answer
    question_id = await QuestionManager.get_question_by_id({"question_text": "how is python?"})
TypeError: get_question_by_id() missing 1 required positional argument: 'question_id'
2021-10-07 23:35:22,934404 - sanic.error - ERROR - Object does not exist
Traceback (most recent call last):
  File "/Users/vivek/Desktop/sanic_3/env/lib/python3.8/site-packages/sanic/app.py", line 770, in handle_request
    response = await response
  File "/Users/vivek/Desktop/sanic_3/app/routes/answer_details.py", line 18, in show_answer_by_id
    _response = await AnswerManager.get_answer_by_id(request, id)
  File "/Users/vivek/Desktop/sanic_3/app/managers/answer_manager.py", line 20, in get_answer_by_id
    answers = await Answers.get(id=answer_id)
  File "/Users/vivek/Desktop/sanic_3/env/lib/python3.8/site-packages/tortoise/queryset.py", line 920, in _execute
    raise DoesNotExist("Object does not exist")
tortoise.exceptions.DoesNotExist: Object does not exist
2021-10-07 23:36:04,800885 - sanic.error - ERROR - protocol.connection_task uncaught
Traceback (most recent call last):
  File "/Users/vivek/Desktop/sanic_3/env/lib/python3.8/site-packages/sanic/http.py", line 130, in http1
    await self.http1_request_header()
  File "/Users/vivek/Desktop/sanic_3/env/lib/python3.8/site-packages/sanic/http.py", line 203, in http1_request_header
    await self._receive_more()
  File "/Users/vivek/Desktop/sanic_3/env/lib/python3.8/site-packages/sanic/server.py", line 222, in receive_more
    await self._data_received.wait()
  File "/Library/Frameworks/Python.framework/Versions/3.8/lib/python3.8/asyncio/locks.py", line 309, in wait
    await fut
asyncio.exceptions.CancelledError

During handling of the above exception, another exception occurred:

Traceback (most recent call last):
  File "/Users/vivek/Desktop/sanic_3/env/lib/python3.8/site-packages/sanic/server.py", line 197, in connection_task
    await self._http.http1()
  File "/Users/vivek/Desktop/sanic_3/env/lib/python3.8/site-packages/sanic/http.py", line 146, in http1
    await self.error_response(e)
  File "/Users/vivek/Desktop/sanic_3/env/lib/python3.8/site-packages/sanic/http.py", line 420, in error_response
    await app.handle_exception(self.request, exception)
  File "/Users/vivek/Desktop/sanic_3/env/lib/python3.8/site-packages/sanic/app.py", line 704, in handle_exception
    await response.send(end_stream=True)
  File "/Users/vivek/Desktop/sanic_3/env/lib/python3.8/site-packages/sanic/response.py", line 122, in send
    await self.stream.send(data, end_stream=end_stream)
  File "/Users/vivek/Desktop/sanic_3/env/lib/python3.8/site-packages/sanic/http.py", line 348, in http1_response_header
    self.log_response()
  File "/Users/vivek/Desktop/sanic_3/env/lib/python3.8/site-packages/sanic/http.py", line 457, in log_response
    extra["request"] = f"{req.method} {req.url}"
  File "/Users/vivek/Desktop/sanic_3/env/lib/python3.8/site-packages/sanic/request.py", line 669, in url
    (self.scheme, self.host, self.path, None, self.query_string, None)
  File "/Users/vivek/Desktop/sanic_3/env/lib/python3.8/site-packages/sanic/request.py", line 596, in scheme
    if self.transport.get_extra_info("sslcontext"):
AttributeError: 'NoneType' object has no attribute 'get_extra_info'
2021-10-07 23:36:22,797008 - sanic.error - ERROR - get_question_by_id() missing 1 required positional argument: 'question_id'
Traceback (most recent call last):
  File "/Users/vivek/Desktop/sanic_3/env/lib/python3.8/site-packages/sanic/app.py", line 770, in handle_request
    response = await response
  File "/Users/vivek/Desktop/sanic_3/app/routes/answer_details.py", line 25, in create_answer
    _response = await AnswerManager.create_answer(request)
  File "/Users/vivek/Desktop/sanic_3/app/managers/answer_manager.py", line 26, in create_answer
    question_id = await QuestionManager.get_question_by_id({"question_text": "how is python?"})
TypeError: get_question_by_id() missing 1 required positional argument: 'question_id'
2021-10-07 23:39:47,579300 - sanic.error - ERROR - get_question_by_id() missing 1 required positional argument: 'question_id'
Traceback (most recent call last):
  File "/Users/vivek/Desktop/sanic_3/env/lib/python3.8/site-packages/sanic/app.py", line 770, in handle_request
    response = await response
  File "/Users/vivek/Desktop/sanic_3/app/routes/answer_details.py", line 25, in create_answer
    payload = await AnswerManager.create_answer(request)
  File "/Users/vivek/Desktop/sanic_3/app/managers/answer_manager.py", line 26, in create_answer
    question_id = await QuestionManager.get_question_by_id({"question_text": "how is python?"})
TypeError: get_question_by_id() missing 1 required positional argument: 'question_id'
2021-10-08 10:37:29,299949 - sanic.error - ERROR - get_question_by_id() missing 1 required positional argument: 'question_id'
Traceback (most recent call last):
  File "/Users/vivek/Desktop/sanic_3/env/lib/python3.8/site-packages/sanic/app.py", line 770, in handle_request
    response = await response
  File "/Users/vivek/Desktop/sanic_3/app/routes/answer_details.py", line 25, in create_answer
    _response = await AnswerManager.create_answer(request)
  File "/Users/vivek/Desktop/sanic_3/app/managers/answer_manager.py", line 27, in create_answer
    question_id = await QuestionManager.get_question_by_id({"id": 22})
TypeError: get_question_by_id() missing 1 required positional argument: 'question_id'
2021-10-08 10:40:26,353185 - sanic.error - ERROR - 'function' object has no attribute 'dumps'
Traceback (most recent call last):
  File "/Users/vivek/Desktop/sanic_3/env/lib/python3.8/site-packages/sanic/app.py", line 770, in handle_request
    response = await response
  File "/Users/vivek/Desktop/sanic_3/app/routes/answer_details.py", line 26, in create_answer
    return send_response({"message": json.dumps(
AttributeError: 'function' object has no attribute 'dumps'
2021-10-08 10:40:27,092801 - sanic.error - ERROR - 'function' object has no attribute 'dumps'
Traceback (most recent call last):
  File "/Users/vivek/Desktop/sanic_3/env/lib/python3.8/site-packages/sanic/app.py", line 770, in handle_request
    response = await response
  File "/Users/vivek/Desktop/sanic_3/app/routes/answer_details.py", line 26, in create_answer
    return send_response({"message": json.dumps(
AttributeError: 'function' object has no attribute 'dumps'
2021-10-08 10:40:27,277587 - sanic.error - ERROR - 'function' object has no attribute 'dumps'
Traceback (most recent call last):
  File "/Users/vivek/Desktop/sanic_3/env/lib/python3.8/site-packages/sanic/app.py", line 770, in handle_request
    response = await response
  File "/Users/vivek/Desktop/sanic_3/app/routes/answer_details.py", line 26, in create_answer
    return send_response({"message": json.dumps(
AttributeError: 'function' object has no attribute 'dumps'
2021-10-08 10:40:27,515008 - sanic.error - ERROR - 'function' object has no attribute 'dumps'
Traceback (most recent call last):
  File "/Users/vivek/Desktop/sanic_3/env/lib/python3.8/site-packages/sanic/app.py", line 770, in handle_request
    response = await response
  File "/Users/vivek/Desktop/sanic_3/app/routes/answer_details.py", line 26, in create_answer
    return send_response({"message": json.dumps(
AttributeError: 'function' object has no attribute 'dumps'
2021-10-08 10:40:27,685892 - sanic.error - ERROR - 'function' object has no attribute 'dumps'
Traceback (most recent call last):
  File "/Users/vivek/Desktop/sanic_3/env/lib/python3.8/site-packages/sanic/app.py", line 770, in handle_request
    response = await response
  File "/Users/vivek/Desktop/sanic_3/app/routes/answer_details.py", line 26, in create_answer
    return send_response({"message": json.dumps(
AttributeError: 'function' object has no attribute 'dumps'
2021-10-08 10:42:07,887167 - sanic.error - ERROR - <Answers: 5> is not JSON serializable
Traceback (most recent call last):
  File "/Users/vivek/Desktop/sanic_3/env/lib/python3.8/site-packages/sanic/app.py", line 770, in handle_request
    response = await response
  File "/Users/vivek/Desktop/sanic_3/app/routes/answer_details.py", line 13, in show_answer
    return send_response(_response)
  File "/Users/vivek/Desktop/sanic_3/env/lib/python3.8/site-packages/torpedo/handlers.py", line 30, in send_response
    return json(body=data, status=status_code)
  File "/Users/vivek/Desktop/sanic_3/env/lib/python3.8/site-packages/sanic/response.py", line 286, in json
    dumps(body, **kwargs),
TypeError: <Answers: 5> is not JSON serializable
2021-10-08 10:42:15,410691 - sanic.error - ERROR - Object does not exist
Traceback (most recent call last):
  File "/Users/vivek/Desktop/sanic_3/env/lib/python3.8/site-packages/sanic/app.py", line 770, in handle_request
    response = await response
  File "/Users/vivek/Desktop/sanic_3/app/routes/answer_details.py", line 18, in show_answer_by_id
    _response = await AnswerManager.get_answer_by_id(request, id)
  File "/Users/vivek/Desktop/sanic_3/app/managers/answer_manager.py", line 20, in get_answer_by_id
    answers = await Answers.get(id=answer_id)
  File "/Users/vivek/Desktop/sanic_3/env/lib/python3.8/site-packages/tortoise/queryset.py", line 920, in _execute
    raise DoesNotExist("Object does not exist")
tortoise.exceptions.DoesNotExist: Object does not exist
2021-10-08 10:42:24,462448 - sanic.error - ERROR - <Answers: 5> is not JSON serializable
Traceback (most recent call last):
  File "/Users/vivek/Desktop/sanic_3/env/lib/python3.8/site-packages/sanic/app.py", line 770, in handle_request
    response = await response
  File "/Users/vivek/Desktop/sanic_3/app/routes/answer_details.py", line 13, in show_answer
    return send_response(_response)
  File "/Users/vivek/Desktop/sanic_3/env/lib/python3.8/site-packages/torpedo/handlers.py", line 30, in send_response
    return json(body=data, status=status_code)
  File "/Users/vivek/Desktop/sanic_3/env/lib/python3.8/site-packages/sanic/response.py", line 286, in json
    dumps(body, **kwargs),
TypeError: <Answers: 5> is not JSON serializable
2021-10-08 10:44:22,693127 - sanic.error - ERROR - 'function' object has no attribute 'dumps'
Traceback (most recent call last):
  File "/Users/vivek/Desktop/sanic_3/env/lib/python3.8/site-packages/sanic/app.py", line 770, in handle_request
    response = await response
  File "/Users/vivek/Desktop/sanic_3/app/routes/answer_details.py", line 13, in show_answer
    return send_response({'message': json.dumps(
AttributeError: 'function' object has no attribute 'dumps'
2021-10-08 10:45:49,806781 - sanic.error - ERROR - Object does not exist
Traceback (most recent call last):
  File "/Users/vivek/Desktop/sanic_3/env/lib/python3.8/site-packages/sanic/app.py", line 770, in handle_request
    response = await response
  File "/Users/vivek/Desktop/sanic_3/app/routes/answer_details.py", line 19, in show_answer_by_id
    _response = await AnswerManager.get_answer_by_id(request, id)
  File "/Users/vivek/Desktop/sanic_3/app/managers/answer_manager.py", line 20, in get_answer_by_id
    answers = await Answers.get(id=answer_id)
  File "/Users/vivek/Desktop/sanic_3/env/lib/python3.8/site-packages/tortoise/queryset.py", line 920, in _execute
    raise DoesNotExist("Object does not exist")
tortoise.exceptions.DoesNotExist: Object does not exist
2021-10-08 11:43:35,652819 - sanic.error - ERROR - type object 'QuestionManager' has no attribute 'get_question_entity_by_id'
Traceback (most recent call last):
  File "/Users/vivek/Desktop/sanic_3/env/lib/python3.8/site-packages/sanic/app.py", line 770, in handle_request
    response = await response
  File "/Users/vivek/Desktop/sanic_3/app/routes/comment_details.py", line 28, in create_comment
    _response = await CommentManager.create_comment(request)
  File "/Users/vivek/Desktop/sanic_3/app/managers/comment_manager.py", line 33, in create_comment
    question_entity_id = await QuestionManager.get_question_entity_by_id({"id":22})
AttributeError: type object 'QuestionManager' has no attribute 'get_question_entity_by_id'
2021-10-08 11:45:53,149321 - sanic.error - ERROR - null value in column "entity_type" of relation "comments" violates not-null constraint
DETAIL:  Failing row contains (1, null, good, 2021-10-08 11:45:53.127582+05:30, 2021-10-08 11:45:53.127605+05:30, 1, 1, 22, 1).
Traceback (most recent call last):
  File "/Users/vivek/Desktop/sanic_3/env/lib/python3.8/site-packages/tortoise/backends/asyncpg/client.py", line 36, in translate_exceptions_
    return await func(self, *args)
  File "/Users/vivek/Desktop/sanic_3/env/lib/python3.8/site-packages/tortoise/backends/asyncpg/client.py", line 150, in execute_insert
    return await connection.fetchrow(query, *values)
  File "/Users/vivek/Desktop/sanic_3/env/lib/python3.8/site-packages/torpedo/clients.py", line 80, in call
    return await wrapped(*args, **kwargs)
  File "/Users/vivek/Desktop/sanic_3/env/lib/python3.8/site-packages/asyncpg/connection.py", line 659, in fetchrow
    data = await self._execute(
  File "/Users/vivek/Desktop/sanic_3/env/lib/python3.8/site-packages/asyncpg/connection.py", line 1639, in _execute
    result, _ = await self.__execute(
  File "/Users/vivek/Desktop/sanic_3/env/lib/python3.8/site-packages/asyncpg/connection.py", line 1664, in __execute
    return await self._do_execute(
  File "/Users/vivek/Desktop/sanic_3/env/lib/python3.8/site-packages/asyncpg/connection.py", line 1711, in _do_execute
    result = await executor(stmt, None)
  File "asyncpg/protocol/protocol.pyx", line 201, in bind_execute
asyncpg.exceptions.NotNullViolationError: null value in column "entity_type" of relation "comments" violates not-null constraint
DETAIL:  Failing row contains (1, null, good, 2021-10-08 11:45:53.127582+05:30, 2021-10-08 11:45:53.127605+05:30, 1, 1, 22, 1).

During handling of the above exception, another exception occurred:

Traceback (most recent call last):
  File "/Users/vivek/Desktop/sanic_3/env/lib/python3.8/site-packages/sanic/app.py", line 770, in handle_request
    response = await response
  File "/Users/vivek/Desktop/sanic_3/app/routes/comment_details.py", line 28, in create_comment
    _response = await CommentManager.create_comment(request)
  File "/Users/vivek/Desktop/sanic_3/app/managers/comment_manager.py", line 37, in create_comment
    answers = await DB.create_instance(Comments, payload)
  File "/Users/vivek/Desktop/sanic_3/app/managers/app/db.py", line 11, in create_instance
    row = await cls.create(model, data)
  File "/Users/vivek/Desktop/sanic_3/env/lib/python3.8/site-packages/torpedo/wrappers/db_wrapper.py", line 57, in create
    row = await model.create(**payload)
  File "/Users/vivek/Desktop/sanic_3/env/lib/python3.8/site-packages/tortoise/models.py", line 1109, in create
    await instance.save(using_db=db, force_create=True)
  File "/Users/vivek/Desktop/sanic_3/env/lib/python3.8/site-packages/tortoise/models.py", line 930, in save
    await executor.execute_insert(self)
  File "/Users/vivek/Desktop/sanic_3/env/lib/python3.8/site-packages/tortoise/backends/base/executor.py", line 217, in execute_insert
    insert_result = await self.db.execute_insert(self.insert_query, values)
  File "/Users/vivek/Desktop/sanic_3/env/lib/python3.8/site-packages/tortoise/backends/asyncpg/client.py", line 40, in translate_exceptions_
    raise IntegrityError(exc)
tortoise.exceptions.IntegrityError: null value in column "entity_type" of relation "comments" violates not-null constraint
DETAIL:  Failing row contains (1, null, good, 2021-10-08 11:45:53.127582+05:30, 2021-10-08 11:45:53.127605+05:30, 1, 1, 22, 1).
2021-10-08 12:12:18,841876 - sanic.error - ERROR - 'function' object has no attribute 'dumps'
Traceback (most recent call last):
  File "/Users/vivek/Desktop/sanic_3/env/lib/python3.8/site-packages/sanic/app.py", line 770, in handle_request
    response = await response
  File "/Users/vivek/Desktop/sanic_3/app/routes/rating_details.py", line 29, in create_rating
    return send_response({"message": json.dumps(
AttributeError: 'function' object has no attribute 'dumps'
2021-10-08 12:18:52,929310 - sanic.error - ERROR - 'function' object has no attribute 'dumps'
Traceback (most recent call last):
  File "/Users/vivek/Desktop/sanic_3/env/lib/python3.8/site-packages/sanic/app.py", line 770, in handle_request
    response = await response
  File "/Users/vivek/Desktop/sanic_3/app/routes/rating_details.py", line 29, in create_rating
    return send_response({"message": json.dumps(
AttributeError: 'function' object has no attribute 'dumps'
2021-10-08 12:19:13,936360 - sanic.error - ERROR - 'function' object has no attribute 'dumps'
Traceback (most recent call last):
  File "/Users/vivek/Desktop/sanic_3/env/lib/python3.8/site-packages/sanic/app.py", line 770, in handle_request
    response = await response
  File "/Users/vivek/Desktop/sanic_3/app/routes/rating_details.py", line 22, in show_rating_by_id
    return send_response({'message': json.dumps(
AttributeError: 'function' object has no attribute 'dumps'
2021-10-08 12:21:13,045915 - sanic.error - ERROR - 'function' object has no attribute 'dumps'
Traceback (most recent call last):
  File "/Users/vivek/Desktop/sanic_3/env/lib/python3.8/site-packages/sanic/app.py", line 770, in handle_request
    response = await response
  File "/Users/vivek/Desktop/sanic_3/app/routes/rating_details.py", line 23, in show_rating_by_id
    return send_response({'message': json.dumps(
AttributeError: 'function' object has no attribute 'dumps'
2021-10-08 12:21:19,766470 - sanic.error - ERROR - 'function' object has no attribute 'dumps'
Traceback (most recent call last):
  File "/Users/vivek/Desktop/sanic_3/env/lib/python3.8/site-packages/sanic/app.py", line 770, in handle_request
    response = await response
  File "/Users/vivek/Desktop/sanic_3/app/routes/rating_details.py", line 16, in show_rating
    return send_response({'message': json.dumps(
AttributeError: 'function' object has no attribute 'dumps'
2021-10-08 12:22:02,328771 - sanic.error - ERROR - protocol.connection_task uncaught
Traceback (most recent call last):
  File "/Users/vivek/Desktop/sanic_3/env/lib/python3.8/site-packages/sanic/http.py", line 130, in http1
    await self.http1_request_header()
  File "/Users/vivek/Desktop/sanic_3/env/lib/python3.8/site-packages/sanic/http.py", line 203, in http1_request_header
    await self._receive_more()
  File "/Users/vivek/Desktop/sanic_3/env/lib/python3.8/site-packages/sanic/server.py", line 222, in receive_more
    await self._data_received.wait()
  File "/Library/Frameworks/Python.framework/Versions/3.8/lib/python3.8/asyncio/locks.py", line 309, in wait
    await fut
asyncio.exceptions.CancelledError

During handling of the above exception, another exception occurred:

Traceback (most recent call last):
  File "/Users/vivek/Desktop/sanic_3/env/lib/python3.8/site-packages/sanic/server.py", line 197, in connection_task
    await self._http.http1()
  File "/Users/vivek/Desktop/sanic_3/env/lib/python3.8/site-packages/sanic/http.py", line 146, in http1
    await self.error_response(e)
  File "/Users/vivek/Desktop/sanic_3/env/lib/python3.8/site-packages/sanic/http.py", line 420, in error_response
    await app.handle_exception(self.request, exception)
  File "/Users/vivek/Desktop/sanic_3/env/lib/python3.8/site-packages/sanic/app.py", line 704, in handle_exception
    await response.send(end_stream=True)
  File "/Users/vivek/Desktop/sanic_3/env/lib/python3.8/site-packages/sanic/response.py", line 122, in send
    await self.stream.send(data, end_stream=end_stream)
  File "/Users/vivek/Desktop/sanic_3/env/lib/python3.8/site-packages/sanic/http.py", line 348, in http1_response_header
    self.log_response()
  File "/Users/vivek/Desktop/sanic_3/env/lib/python3.8/site-packages/sanic/http.py", line 457, in log_response
    extra["request"] = f"{req.method} {req.url}"
  File "/Users/vivek/Desktop/sanic_3/env/lib/python3.8/site-packages/sanic/request.py", line 669, in url
    (self.scheme, self.host, self.path, None, self.query_string, None)
  File "/Users/vivek/Desktop/sanic_3/env/lib/python3.8/site-packages/sanic/request.py", line 596, in scheme
    if self.transport.get_extra_info("sslcontext"):
AttributeError: 'NoneType' object has no attribute 'get_extra_info'
